<?xml version="1.0" ?>
<robot name="ur3_robotiq">
  <material name="Grey"> <color rgba="0.7 0.7 0.7 1.0"/> </material>
  <material name="Blue"> <color rgba="0.1 0.4 0.8 1.0"/> </material>

  <link name="base_link">
    <visual> <geometry> <cylinder length="0.05" radius="0.06"/> </geometry> <material name="Grey"/> </visual>
    <inertial> <mass value="2.0"/> <inertia ixx="0.01" ixy="0" ixz="0" iyy="0.01" iyz="0" izz="0.01"/> </inertial>
  </link>

  <joint name="shoulder_pan_joint" type="revolute">
    <parent link="base_link"/> <child link="shoulder_link"/>
    <origin xyz="0 0 0.05"/> <axis xyz="0 0 1"/> 
    <limit effort="330" lower="-6.28" upper="6.28" velocity="2.16"/>
  </joint>

  <link name="shoulder_link">
    <inertial> <mass value="2.0"/> <inertia ixx="0.01" ixy="0" ixz="0" iyy="0.01" iyz="0" izz="0.01"/> </inertial>
  </link>

  <joint name="shoulder_lift_joint" type="revolute">
    <parent link="shoulder_link"/> <child link="upper_arm_link"/>
    <origin xyz="0 0.1 0.05"/> <axis xyz="0 1 0"/> 
    <limit effort="330" lower="-6.28" upper="6.28" velocity="2.16"/>
  </joint>

  <link name="upper_arm_link">
    <inertial> <mass value="3.42"/> <inertia ixx="0.02" ixy="0" ixz="0" iyy="0.02" iyz="0" izz="0.02"/> </inertial>
  </link>

  <joint name="elbow_joint" type="revolute">
    <parent link="upper_arm_link"/> <child link="forearm_link"/>
    <origin xyz="0 -0.05 0.24"/> <axis xyz="0 1 0"/> 
    <limit effort="150" lower="-3.14" upper="3.14" velocity="3.15"/>
  </joint>

  <link name="forearm_link">
    <inertial> <mass value="1.26"/> <inertia ixx="0.01" ixy="0" ixz="0" iyy="0.01" iyz="0" izz="0.01"/> </inertial>
  </link>

  <joint name="wrist_joint" type="revolute">
    <parent link="forearm_link"/> <child link="wrist_link"/>
    <origin xyz="0 0 0.21"/> <axis xyz="0 1 0"/> 
    <limit effort="54" lower="-6.28" upper="6.28" velocity="3.2"/>
  </joint>

  <link name="wrist_link">
    <inertial> <mass value="0.5"/> <inertia ixx="0.001" ixy="0" ixz="0" iyy="0.001" iyz="0" izz="0.001"/> </inertial>
  </link>

  <joint name="gripper_base_joint" type="fixed">
    <parent link="wrist_link"/> <child link="gripper_base"/>
    <origin xyz="0 0 0.05"/>
  </joint>

  <link name="gripper_base">
    <visual> <geometry> <box size="0.06 0.04 0.04"/> </geometry> <material name="Grey"/> </visual>
    <inertial> <mass value="0.3"/> <inertia ixx="0.001" ixy="0" ixz="0" iyy="0.001" iyz="0" izz="0.001"/> </inertial>
  </link>

  <joint name="f1" type="prismatic"> <parent link="gripper_base"/> <child link="l_finger"/> <axis xyz="0 1 0"/> <limit effort="50" lower="-0.04" upper="0"/> </joint>
  <link name="l_finger"> <visual> <origin xyz="0 0.03 0.04"/> <geometry> <box size="0.01 0.01 0.06"/> </geometry> </visual> </link>
  <joint name="f2" type="prismatic"> <parent link="gripper_base"/> <child link="r_finger"/> <axis xyz="0 1 0"/> <limit effort="50" lower="0" upper="0.04"/> </joint>
  <link name="r_finger"> <visual> <origin xyz="0 -0.03 0.04"/> <geometry> <box size="0.01 0.01 0.06"/> </geometry> </visual> </link>
</robot>